<?xml version="1.0"?>
<robot xmlns:xacro="http://www.ros.org/wiki/xacro">

  <xacro:macro name="wheel" params="name x y z radius width">
    <link name="${name}_wheel">
      <visual>
        <geometry>
          <cylinder radius="${radius}" length="${width}"/>
        </geometry>
        <material name="wheel_black">
          <color rgba="0.1 0.1 0.1 1.0"/>
        </material>
      </visual>
      <collision>
        <geometry>
          <cylinder radius="${radius}" length="${width}"/>
        </geometry>
      </collision>
      <inertial>
        <mass value="2.0"/>
        <inertia ixx="0.002" ixy="0" ixz="0" iyy="0.002" iyz="0" izz="0.002"/>
      </inertial>
    </link>

    <joint name="${name}_wheel_joint" type="continuous">
      <parent link="base_link"/>
      <child link="${name}_wheel"/>
      <origin xyz="${x} ${y} ${z}" rpy="${-pi/2} 0 0"/>
      <axis xyz="0 0 1"/>
    </joint>
  </xacro:macro>

</robot>
